Workbook
Name HeuresStandardJour: '00_Parametres'!$B$5
Name HeuresStandardMois: '00_Parametres'!$B$7
Name JoursStandardMois: '00_Parametres'!$B$6
Name SeuilHS: '00_Parametres'!$B$9
Name TauxMajorationHS: '00_Parametres'!$B$8

Sheet 00_Dashboard
A1: GARAGE POLYVALENT JUNIOR — TABLEAU DE BORD RH
A2: Mis à jour automatiquement | Fichier professionnel v2.0
A4: INDICATEURS CLÉS
A5: EFFECTIF TOTAL | C5: ACTIFS | E5: CDI | G5: APPRENTISSAGE
A6: =SUMPRODUCT(('01_Employes'!A6:A30<>"")*1) -> 14 | C6: =COUNTIF('01_Employes'!I6:I30,"Actif") -> 14 | E6: =COUNTIF('01_Employes'!K6:K30,"CDI") -> 4 | G6: =COUNTIF('01_Employes'!K6:K30,"Apprentissage") -> 9
A8: MASSE SALARIALE BASE (FCFA) | D8: NBR DÉPARTEMENTS
A9: =SUMIF('01_Employes'!I6:I30,"Actif",'01_Employes'!L6:L30) -> 1440000 | D9: 5
A11: RÉPARTITION PAR POSTE | D11: RÉPARTITION PAR DÉPARTEMENT
A12: Poste | B12: Nombre | D12: Département | E12: Nombre
A13: Administrateur | B13: =COUNTIF('01_Employes'!E$6:E$30,A13) -> 1 | D13: Administration | E13: =COUNTIF('01_Employes'!F$6:F$30,D13) -> 3
A14: Secrétaire | B14: =COUNTIF('01_Employes'!E$6:E$30,A14) -> 1 | D14: Direction Atelier | E14: =COUNTIF('01_Employes'!F$6:F$30,D14) -> 1
A15: Chef des ateliers | B15: =COUNTIF('01_Employes'!E$6:E$30,A15) -> 1 | D15: Atelier Mécanique | E15: =COUNTIF('01_Employes'!F$6:F$30,D15) -> 8
A16: Mécanicien | B16: =COUNTIF('01_Employes'!E$6:E$30,A16) -> 7 | D16: Carrosserie | E16: =COUNTIF('01_Employes'!F$6:F$30,D16) -> 1
A17: Tôlier | B17: =COUNTIF('01_Employes'!E$6:E$30,A17) -> 1 | D17: Magasin | E17: =COUNTIF('01_Employes'!F$6:F$30,D17) -> 1
A18: Magasinier | B18: =COUNTIF('01_Employes'!E$6:E$30,A18) -> 1
A19: Électronicien | B19: =COUNTIF('01_Employes'!E$6:E$30,A19) -> 1
A20: Assistant Administratif | B20: =COUNTIF('01_Employes'!E$6:E$30,A20) -> 1
A23: ACCÈS RAPIDE AUX MODULES
A24: Module | B24: Description
A25: 01_Employes | B25: Fiche complète de chaque employé (identité, contact, poste, contrat, salaire...)
A26: 02_Pointage | B26: Pointage journalier avec heures d'arrivée/départ + primes de tâche
A27: 03_Paie | B27: Calcul automatique du salaire sur heures réelles + primes + HS
A28: 04_Conges | B28: Demandes et suivi des congés / absences + soldes
A29: 05_Contrats | B29: Informations contractuelles et documents
A30: 06_Competences | B30: Compétences, formations et habilitations
A31: 07_Planning | B31: Planning hebdomadaire / affectations
A32: 08_Sanctions | B32: Avertissements, incidents, remarques
A33: 09_Contacts | B33: Annuaire interne prêt à l'emploi
A34: 00_Parametres | B34: Paramètres globaux (heures standard, majoration HS...)

Sheet 00_Parametres
A1: PARAMÈTRES GÉNÉRAUX — GARAGE POLYVALENT JUNIOR
A3: HORAIRES DE TRAVAIL HEBDOMADAIRES (100% MODIFIABLES)
A4: Modifiez librement les jours travaillés (Oui/Non), les heures d'arrivée/départ et la durée de pause. Tous les calculs se mettent à jour automatiquement.
A6: Jour | B6: Travaillé ? (Oui/Non) | C6: Heure Début | D6: Heure Fin | E6: Pause (heures) | F6: Heures nettes / jour | G6: Notes
A7: Lundi | B7: Oui | C7: 0.3125 | D7: 0.75 | E7: 1 | F7: =IF(B7="Oui",IF(OR(C7="",D7=""),0,ROUND((D7-C7)*24-E7,2)),0) -> 9.5 | G7: Jour normal
A8: Mardi | B8: Oui | C8: 0.3125 | D8: 0.75 | E8: 1 | F8: =IF(B8="Oui",IF(OR(C8="",D8=""),0,ROUND((D8-C8)*24-E8,2)),0) -> 9.5 | G8: Jour normal
A9: Mercredi | B9: Oui | C9: 0.3125 | D9: 0.75 | E9: 1 | F9: =IF(B9="Oui",IF(OR(C9="",D9=""),0,ROUND((D9-C9)*24-E9,2)),0) -> 9.5 | G9: Jour normal
A10: Jeudi | B10: Oui | C10: 0.3125 | D10: 0.75 | E10: 1 | F10: =IF(B10="Oui",IF(OR(C10="",D10=""),0,ROUND((D10-C10)*24-E10,2)),0) -> 9.5 | G10: Jour normal
A11: Vendredi | B11: Oui | C11: 0.3125 | D11: 0.75 | E11: 1 | F11: =IF(B11="Oui",IF(OR(C11="",D11=""),0,ROUND((D11-C11)*24-E11,2)),0) -> 9.5 | G11: Jour normal
A12: Samedi | B12: Oui | C12: 0.3125 | D12: 0.5 | E12: 0 | F12: =IF(B12="Oui",IF(OR(C12="",D12=""),0,ROUND((D12-C12)*24-E12,2)),0) -> 4.5 | G12: Matin seulement
A13: Dimanche | B13: Non | E13: 0 | F13: =IF(B13="Oui",IF(OR(C13="",D13=""),0,ROUND((D13-C13)*24-E13,2)),0) -> 0 | G13: Repos
A15: RÉSUMÉ HEBDOMADAIRE (calculé automatiquement)
A16: Jours travaillés / semaine | B16: =COUNTIF(B7:B13,"Oui") -> 6
A17: Heures nettes / semaine | B17: =SUM(F7:F13) -> 52
A18: Heures standard / mois (≈ 4,333 semaines) | B18: =ROUND(B17*4.333,1) -> 225.3 | C18: ← Utilisée pour calculer le taux horaire des employés
A20: PARAMÈTRES GÉNÉRAUX DE CALCUL & RÈGLES DE POINTAGE
A21: Heures standard mensuelles (pour taux horaire) | B21: =B18 -> 225.3
A22: Taux majoration Heures Supp. (ex: 1.5 = +50%) | B22: 1.5
A23: Seuil HS journalier (heures) — au-delà = heures supplémentaires | B23: 9.5
A24: Heures standard d'un jour de semaine (référence) | B24: =F7 -> 9.5
A25: Heures standard d'un samedi (référence) | B25: =F12 -> 4.5
A27: RÈGLES DE COMPTABILISATION DES HEURES (modifiables par l'Admin)
A28: Comptabiliser les arrivées anticipées ? (Oui = extra payé / Non = plafonné à l'heure de début) | B28: Non | C28: Par défaut NON : arriver avant l'heure ne rapporte pas d'heures supplémentaires
A29: Comptabiliser les départs tardifs ? (Oui = extra payé / Non = plafonné à l'heure de fin) | B29: Non | C29: Par défaut NON : rester après l'heure ne rapporte pas d'heures supplémentaires (sauf validation ligne par ligne)
A30: Déduire automatiquement les retards ? | B30: Oui | C30: Absence non justifiée
A31: Déduire automatiquement les départs anticipés ? | B31: Oui | C31: Congé approuvé
A32: M | B32: Maladie | C32: Arrêt maladie
A33: LOGIQUE APPLIQUÉE DANS LE POINTAGE | B33: Retard | C33: Présent avec retard
A34: 1. Arrivée avant l'heure de début → considérée comme arrivée à l'heure (sauf si Admin valide l'anticipation sur la ligne). | B34: Jour Travaillé partiel | C34: Journée partielle
A35: 2. Départ après l'heure de fin → considéré comme départ à l'heure (sauf si Admin valide le départ tardif sur la ligne). | B35: Heures Supplémentaires | C35: Journée avec HS
A36: 3. Arrivée en retard → les minutes de retard sont déduites du temps de travail. | B36: Férié | C36: Jour férié
A37: 4. Départ anticipé → les minutes manquantes sont déduites du temps de travail.
A38: 5. Tous les calculs se font d'abord en minutes, puis conversion en heures décimales (précision maximale).
A39: Postes | B39: Départements | C39: Types de contrat | D39: Statuts | E39: Types d'absence
A40: Administrateur | B40: Administration | C40: CDI | D40: Actif | E40: Congé annuel
A41: Secrétaire | B41: Direction Atelier | C41: CDD | D41: Inactif | E41: Congé maladie
A42: Chef des ateliers | B42: Atelier Mécanique | C42: Apprentissage | D42: Suspendu | E42: Congé maternité
A43: Mécanicien | B43: Carrosserie | C43: Stage | D43: Démissionnaire | E43: Congé sans solde
A44: Tôlier | B44: Magasin | C44: Journalier | D44: Licencié | E44: Absence injustifiée
A45: Magasinier | B45: Direction Générale | C45: Prestataire | E45: Formation
...

Sheet 01_Employes
A1: REGISTRE DU PERSONNEL — GARAGE POLYVALENT JUNIOR
A2: SOURCE DE VÉRITÉ — Toute modification ici se propage automatiquement aux autres feuilles via les formules.
A3: Complétez uniquement les cellules JAUNES. Les colonnes vertes sont calculées automatiquement.
A5: ID | B5: Nom | C5: Prénom | D5: Nom Complet | E5: Poste | F5: Département | G5: Téléphone | H5: Email | I5: Statut | J5: Date d'embauche | K5: Type de contrat | L5: Salaire Base Mensuel (FCFA) | M5: Taux Horaire (FCFA) | N5: Taux HS (FCFA) | O5: N° CNPS | P5: Adresse | Q5: Notes / Observations
A6: EMP001 | B6: Tsafack Ndongmo | C6: Symphonien | D6: =TRIM(B6&" "&C6) -> Tsafack Ndongmo Symphonien | E6: Administrateur | F6: Administration | G6: 677 89 71 62 | I6: Actif | K6: CDI | L6: 150000 | M6: =IF(L6="","",ROUND(L6/'00_Parametres'!$B$21,0)) -> 666 | N6: =IF(M6="","",ROUND(M6*'00_Parametres'!$B$22,0)) -> 999
A7: EMP002 | B7: Pandja Tchatchoua | C7: Syriane | D7: =TRIM(B7&" "&C7) -> Pandja Tchatchoua Syriane | E7: Secrétaire | F7: Administration | G7: 656 04 71 31 | I7: Actif | K7: CDI | L7: 100000 | M7: =IF(L7="","",ROUND(L7/'00_Parametres'!$B$21,0)) -> 444 | N7: =IF(M7="","",ROUND(M7*'00_Parametres'!$B$22,0)) -> 666
A8: EMP003 | B8: Takoueta | C8: Yvan | D8: =TRIM(B8&" "&C8) -> Takoueta Yvan | E8: Chef des ateliers | F8: Direction Atelier | G8: 657 78 99 78 | I8: Actif | K8: CDI | L8: 150000 | M8: =IF(L8="","",ROUND(L8/'00_Parametres'!$B$21,0)) -> 666 | N8: =IF(M8="","",ROUND(M8*'00_Parametres'!$B$22,0)) -> 999
A9: EMP004 | B9: Chekep | C9: Faustin | D9: =TRIM(B9&" "&C9) -> Chekep Faustin | E9: Mécanicien | F9: Atelier Mécanique | G9: 672 67 18 01 | I9: Actif | K9: CDI | L9: 120000 | M9: =IF(L9="","",ROUND(L9/'00_Parametres'!$B$21,0)) -> 533 | N9: =IF(M9="","",ROUND(M9*'00_Parametres'!$B$22,0)) -> 800
A10: EMP005 | B10: Abdou | D10: =TRIM(B10&" "&C10) -> Abdou | E10: Tôlier | F10: Carrosserie | G10: 673 84 48 12 | I10: Actif | K10: Apprentissage | L10: 80000 | M10: =IF(L10="","",ROUND(L10/'00_Parametres'!$B$21,0)) -> 355 | N10: =IF(M10="","",ROUND(M10*'00_Parametres'!$B$22,0)) -> 533
A11: EMP006 | B11: Nyontyen Si | C11: Jean Vinny | D11: =TRIM(B11&" "&C11) -> Nyontyen Si Jean Vinny | E11: Mécanicien | F11: Atelier Mécanique | G11: 694 36 28 38 | I11: Actif | K11: Apprentissage | L11: 80000 | M11: =IF(L11="","",ROUND(L11/'00_Parametres'!$B$21,0)) -> 355 | N11: =IF(M11="","",ROUND(M11*'00_Parametres'!$B$22,0)) -> 533
A12: EMP007 | B12: Holé | C12: Homsala | D12: =TRIM(B12&" "&C12) -> Holé Homsala | E12: Magasinier | F12: Magasin | G12: 699 47 09 80 | H12: holehomsala7@gmail.com | I12: Actif | K12: Apprentissage | L12: 80000 | M12: =IF(L12="","",ROUND(L12/'00_Parametres'!$B$21,0)) -> 355 | N12: =IF(M12="","",ROUND(M12*'00_Parametres'!$B$22,0)) -> 533
A13: EMP008 | B13: Ebene | C13: Ngono | D13: =TRIM(B13&" "&C13) -> Ebene Ngono | E13: Mécanicien | F13: Atelier Mécanique | G13: 653 04 86 11 | I13: Actif | K13: Apprentissage | L13: 80000 | M13: =IF(L13="","",ROUND(L13/'00_Parametres'!$B$21,0)) -> 355 | N13: =IF(M13="","",ROUND(M13*'00_Parametres'!$B$22,0)) -> 533
A14: EMP009 | B14: Tineba | C14: Vital Eric | D14: =TRIM(B14&" "&C14) -> Tineba Vital Eric | E14: Mécanicien | F14: Atelier Mécanique | G14: 698 14 24 06 | I14: Actif | K14: Apprentissage | L14: 80000 | M14: =IF(L14="","",ROUND(L14/'00_Parametres'!$B$21,0)) -> 355 | N14: =IF(M14="","",ROUND(M14*'00_Parametres'!$B$22,0)) -> 533
A15: EMP010 | B15: Deutchoua Tientcheu | C15: Christian | D15: =TRIM(B15&" "&C15) -> Deutchoua Tientcheu Christian | E15: Mécanicien | F15: Atelier Mécanique | G15: 695 07 89 78 / 678 03 61 47 | I15: Actif | K15: Apprentissage | L15: 80000 | M15: =IF(L15="","",ROUND(L15/'00_Parametres'!$B$21,0)) -> 355 | N15: =IF(M15="","",ROUND(M15*'00_Parametres'!$B$22,0)) -> 533
A16: EMP011 | B16: Fouakouet | C16: Youssoufa | D16: =TRIM(B16&" "&C16) -> Fouakouet Youssoufa | E16: Électronicien | F16: Atelier Mécanique | G16: 640 85 90 53 / 620 04 32 29 | I16: Actif | K16: Apprentissage | L16: 80000 | M16: =IF(L16="","",ROUND(L16/'00_Parametres'!$B$21,0)) -> 355 | N16: =IF(M16="","",ROUND(M16*'00_Parametres'!$B$22,0)) -> 533
A17: EMP012 | B17: Ngouamera | C17: Adrien Gildas | D17: =TRIM(B17&" "&C17) -> Ngouamera Adrien Gildas | E17: Mécanicien | F17: Atelier Mécanique | G17: 680 09 48 64 | I17: Actif | K17: Apprentissage | L17: 80000 | M17: =IF(L17="","",ROUND(L17/'00_Parametres'!$B$21,0)) -> 355 | N17: =IF(M17="","",ROUND(M17*'00_Parametres'!$B$22,0)) -> 533
A18: EMP013 | B18: Nague Zemdjui | C18: Arnaud | D18: =TRIM(B18&" "&C18) -> Nague Zemdjui Arnaud | E18: Assistant Administratif | F18: Administration | G18: 658 77 57 44 | H18: arnaudstars@gmail.com | I18: Actif | K18: CDD | L18: 200000 | M18: =IF(L18="","",ROUND(L18/'00_Parametres'!$B$21,0)) -> 888 | N18: =IF(M18="","",ROUND(M18*'00_Parametres'!$B$22,0)) -> 1332
A19: EMP014 | B19: Zo'o Mbarga | C19: Jean Loic | D19: =IF(B19="","",TRIM(B19&" "&C19)) -> Zo'o Mbarga Jean Loic | E19: Mécanicien | F19: Atelier Mécanique | G19: 698 94 92 21 | I19: Actif | J19: 46223 | K19: Apprentissage | L19: 80000 | M19: =IF(L19="","",ROUND(L19/'00_Parametres'!$B$21,0)) -> 355 | N19: =IF(M19="","",ROUND(M19*'00_Parametres'!$B$22,0)) -> 533
D20: =IF(B20="","",TRIM(B20&" "&C20)) | M20: =IF(L20="","",ROUND(L20/'00_Parametres'!$B$21,0)) | N20: =IF(M20="","",ROUND(M20*'00_Parametres'!$B$22,0))
D21: =IF(B21="","",TRIM(B21&" "&C21)) | M21: =IF(L21="","",ROUND(L21/'00_Parametres'!$B$21,0)) | N21: =IF(M21="","",ROUND(M21*'00_Parametres'!$B$22,0))
D22: =IF(B22="","",TRIM(B22&" "&C22)) | M22: =IF(L22="","",ROUND(L22/'00_Parametres'!$B$21,0)) | N22: =IF(M22="","",ROUND(M22*'00_Parametres'!$B$22,0))
D23: =IF(B23="","",TRIM(B23&" "&C23)) | M23: =IF(L23="","",ROUND(L23/'00_Parametres'!$B$21,0)) | N23: =IF(M23="","",ROUND(M23*'00_Parametres'!$B$22,0))
D24: =IF(B24="","",TRIM(B24&" "&C24)) | M24: =IF(L24="","",ROUND(L24/'00_Parametres'!$B$21,0)) | N24: =IF(M24="","",ROUND(M24*'00_Parametres'!$B$22,0))
D25: =IF(B25="","",TRIM(B25&" "&C25)) | M25: =IF(L25="","",ROUND(L25/'00_Parametres'!$B$21,0)) | N25: =IF(M25="","",ROUND(M25*'00_Parametres'!$B$22,0))

Sheet 02_Pointage
A1: POINTAGE GPJ 2026
A2: ASTUCE UX : Pour un même jour, saisissez la Date une fois puis copiez-la vers le bas (Ctrl+D). Ou filtrez par date. Les heures se calculent automatiquement.
A3: Légende : JAUNE = saisie | VERT = calculé auto | ORANGE = validation Admin (Oui pour compter l'extra)
A5: Date | B5: ID Employé | C5: Nom Complet | D5: Jour | E5: H. Début théorique | F5: H. Fin théorique | G5: Pause (h) | H5: Heure Arrivée réelle | I5: Heure Départ réelle | J5: Valider arrivée anticipée ? | K5: Valider départ tardif ? | L5: Arrivée effective | M5: Départ effectif | N5: Minutes de retard | O5: Minutes départ anticipé | P5: Heures travaillées | Q5: Heures Normales | R5: Heures Supp. | S5: Code Présence | T5: Prime Tâche (FCFA) | U5: Notes / Motif
A6: 46258 | B6: EMP001 | C6: =IF(B6="","",IFERROR(VLOOKUP(B6,Employes[[ID]:[Nom Complet]],4,FALSE()),"")) -> Tsafack Ndongmo Symphonien | D6: =IF(A6="","",TEXT(A6,"dddd")) -> dddd | E6: =IF(A6="","",IFERROR(INDEX('00_Parametres'!$C$7:$C$13,WEEKDAY(A6,2)),"")) -> 0.3125 | F6: =IF(A6="","",IFERROR(INDEX('00_Parametres'!$D$7:$D$13,WEEKDAY(A6,2)),"")) -> 0.75 | G6: =IF(A6="","",IFERROR(INDEX('00_Parametres'!$E$7:$E$13,WEEKDAY(A6,2)),0)) -> 1 | H6: 0.30208333 | I6: 0.75694444 | J6: Non | K6: Non | L6: =IF(OR(A6="",H6=""),"",IF(H6<E6,IF(OR(J6="Oui",'00_Parametres'!$B$28="Oui"),H6,E6),H6)) -> 0.3125 | M6: =IF(OR(A6="",I6=""),"",IF(I6>F6,IF(OR(K6="Oui",'00_Parametres'!$B$29="Oui"),I6,F6),I6)) -> 0.75 | N6: =IF(OR(A6="",H6="",E6=""),0,MAX(0,ROUND((H6-E6)*1440,0))) -> 0 | O6: =IF(OR(A6="",I6="",F6=""),0,MAX(0,ROUND((F6-I6)*1440,0))) -> 0 | P6: =IF(OR(L6="",M6=""),0,MAX(0,ROUND((M6-L6)*24-G6,2))) -> 9.5 | Q6: =IF(P6=0,0,MIN(P6,'00_Parametres'!$B$23)) -> 9.5 | R6: =IF(P6=0,0,MAX(0,P6-'00_Parametres'!$B$23)) -> 0 | S6: A | T6: 0 | U6: Arrivé 15 min avant → non compté
A7: 46258 | B7: EMP002 | C7: =IF(B7="","",IFERROR(VLOOKUP(B7,Employes[[ID]:[Nom Complet]],4,FALSE()),"")) -> Pandja Tchatchoua Syriane | D7: =IF(A7="","",TEXT(A7,"dddd")) -> dddd | E7: =IF(A7="","",IFERROR(INDEX('00_Parametres'!$C$7:$C$13,WEEKDAY(A7,2)),"")) -> 0.3125 | F7: =IF(A7="","",IFERROR(INDEX('00_Parametres'!$D$7:$D$13,WEEKDAY(A7,2)),"")) -> 0.75 | G7: =IF(A7="","",IFERROR(INDEX('00_Parametres'!$E$7:$E$13,WEEKDAY(A7,2)),0)) -> 1 | H7: 0.3125 | I7: 0.79166667 | J7: Non | K7: Oui | L7: =IF(OR(A7="",H7=""),"",IF(H7<E7,IF(OR(J7="Oui",'00_Parametres'!$B$28="Oui"),H7,E7),H7)) -> 0.3125 | M7: =IF(OR(A7="",I7=""),"",IF(I7>F7,IF(OR(K7="Oui",'00_Parametres'!$B$29="Oui"),I7,F7),I7)) -> 0.79166667 | N7: =IF(OR(A7="",H7="",E7=""),0,MAX(0,ROUND((H7-E7)*1440,0))) -> 0 | O7: =IF(OR(A7="",I7="",F7=""),0,MAX(0,ROUND((F7-I7)*1440,0))) -> 0 | P7: =IF(OR(L7="",M7=""),0,MAX(0,ROUND((M7-L7)*24-G7,2))) -> 10.5 | Q7: =IF(P7=0,0,MIN(P7,'00_Parametres'!$B$23)) -> 9.5 | R7: =IF(P7=0,0,MAX(0,P7-'00_Parametres'!$B$23)) -> 1 | S7: HS | T7: 5000 | U7: Départ tardif validé Admin
A8: 46258 | B8: EMP003 | C8: =IF(B8="","",IFERROR(VLOOKUP(B8,Employes[[ID]:[Nom Complet]],4,FALSE()),"")) -> Takoueta Yvan | D8: =IF(A8="","",TEXT(A8,"dddd")) -> dddd | E8: =IF(A8="","",IFERROR(INDEX('00_Parametres'!$C$7:$C$13,WEEKDAY(A8,2)),"")) -> 0.3125 | F8: =IF(A8="","",IFERROR(INDEX('00_Parametres'!$D$7:$D$13,WEEKDAY(A8,2)),"")) -> 0.75 | G8: =IF(A8="","",IFERROR(INDEX('00_Parametres'!$E$7:$E$13,WEEKDAY(A8,2)),0)) -> 1 | H8: 0.33333333 | I8: 0.72916667 | J8: Non | K8: Non | L8: =IF(OR(A8="",H8=""),"",IF(H8<E8,IF(OR(J8="Oui",'00_Parametres'!$B$28="Oui"),H8,E8),H8)) -> 0.33333333 | M8: =IF(OR(A8="",I8=""),"",IF(I8>F8,IF(OR(K8="Oui",'00_Parametres'!$B$29="Oui"),I8,F8),I8)) -> 0.72916667 | N8: =IF(OR(A8="",H8="",E8=""),0,MAX(0,ROUND((H8-E8)*1440,0))) -> 30 | O8: =IF(OR(A8="",I8="",F8=""),0,MAX(0,ROUND((F8-I8)*1440,0))) -> 30 | P8: =IF(OR(L8="",M8=""),0,MAX(0,ROUND((M8-L8)*24-G8,2))) -> 8.5 | Q8: =IF(P8=0,0,MIN(P8,'00_Parametres'!$B$23)) -> 8.5 | R8: =IF(P8=0,0,MAX(0,P8-'00_Parametres'!$B$23)) -> 0 | S8: R | T8: 0 | U8: Retard 30 min + départ anticipé 30 min
A9: 46258 | B9: EMP004 | C9: =IF(B9="","",IFERROR(VLOOKUP(B9,Employes[[ID]:[Nom Complet]],4,FALSE()),"")) -> Chekep Faustin | D9: =IF(A9="","",TEXT(A9,"dddd")) -> dddd | E9: =IF(A9="","",IFERROR(INDEX('00_Parametres'!$C$7:$C$13,WEEKDAY(A9,2)),"")) -> 0.3125 | F9: =IF(A9="","",IFERROR(INDEX('00_Parametres'!$D$7:$D$13,WEEKDAY(A9,2)),"")) -> 0.75 | G9: =IF(A9="","",IFERROR(INDEX('00_Parametres'!$E$7:$E$13,WEEKDAY(A9,2)),0)) -> 1 | H9: 0.32291667 | I9: 0.75 | J9: Non | K9: Non | L9: =IF(OR(A9="",H9=""),"",IF(H9<E9,IF(OR(J9="Oui",'00_Parametres'!$B$28="Oui"),H9,E9),H9)) -> 0.32291667 | M9: =IF(OR(A9="",I9=""),"",IF(I9>F9,IF(OR(K9="Oui",'00_Parametres'!$B$29="Oui"),I9,F9),I9)) -> 0.75 | N9: =IF(OR(A9="",H9="",E9=""),0,MAX(0,ROUND((H9-E9)*1440,0))) -> 15 | O9: =IF(OR(A9="",I9="",F9=""),0,MAX(0,ROUND((F9-I9)*1440,0))) -> 0 | P9: =IF(OR(L9="",M9=""),0,MAX(0,ROUND((M9-L9)*24-G9,2))) -> 9.25 | Q9: =IF(P9=0,0,MIN(P9,'00_Parametres'!$B$23)) -> 9.25 | R9: =IF(P9=0,0,MAX(0,P9-'00_Parametres'!$B$23)) -> 0 | S9: R | T9: 0 | U9: Retard 15 min
A10: 46258 | B10: EMP005 | C10: =IF(B10="","",IFERROR(VLOOKUP(B10,Employes[[ID]:[Nom Complet]],4,FALSE()),"")) -> Abdou | D10: =IF(A10="","",TEXT(A10,"dddd")) -> dddd | E10: =IF(A10="","",IFERROR(INDEX('00_Parametres'!$C$7:$C$13,WEEKDAY(A10,2)),"")) -> 0.3125 | F10: =IF(A10="","",IFERROR(INDEX('00_Parametres'!$D$7:$D$13,WEEKDAY(A10,2)),"")) -> 0.75 | G10: =IF(A10="","",IFERROR(INDEX('00_Parametres'!$E$7:$E$13,WEEKDAY(A10,2)),0)) -> 1 | H10: 0.3125 | I10: 0.5 | J10: Non | K10: Non | L10: =IF(OR(A10="",H10=""),"",IF(H10<E10,IF(OR(J10="Oui",'00_Parametres'!$B$28="Oui"),H10,E10),H10)) -> 0.3125 | M10: =IF(OR(A10="",I10=""),"",IF(I10>F10,IF(OR(K10="Oui",'00_Parametres'!$B$29="Oui"),I10,F10),I10)) -> 0.5 | N10: =IF(OR(A10="",H10="",E10=""),0,MAX(0,ROUND((H10-E10)*1440,0))) -> 0 | O10: =IF(OR(A10="",I10="",F10=""),0,MAX(0,ROUND((F10-I10)*1440,0))) -> 360 | P10: =IF(OR(L10="",M10=""),0,MAX(0,ROUND((M10-L10)*24-G10,2))) -> 3.5 | Q10: =IF(P10=0,0,MIN(P10,'00_Parametres'!$B$23)) -> 3.5 | R10: =IF(P10=0,0,MAX(0,P10-'00_Parametres'!$B$23)) -> 0 | S10: P | T10: 2500 | U10: Samedi normal 7h30-12h
A11: 46258 | B11: EMP006 | C11: =IF(B11="","",IFERROR(VLOOKUP(B11,Employes[[ID]:[Nom Complet]],4,FALSE()),"")) -> Nyontyen Si Jean Vinny | D11: =IF(A11="","",TEXT(A11,"dddd")) -> dddd | E11: =IF(A11="","",IFERROR(INDEX('00_Parametres'!$C$7:$C$13,WEEKDAY(A11,2)),"")) -> 0.3125 | F11: =IF(A11="","",IFERROR(INDEX('00_Parametres'!$D$7:$D$13,WEEKDAY(A11,2)),"")) -> 0.75 | G11: =IF(A11="","",IFERROR(INDEX('00_Parametres'!$E$7:$E$13,WEEKDAY(A11,2)),0)) -> 1 | H11: 0.3125 | I11: 0.79166667 | J11: Non | K11: Non | L11: =IF(OR(A11="",H11=""),"",IF(H11<E11,IF(OR(J11="Oui",'00_Parametres'!$B$28="Oui"),H11,E11),H11)) -> 0.3125 | M11: =IF(OR(A11="",I11=""),"",IF(I11>F11,IF(OR(K11="Oui",'00_Parametres'!$B$29="Oui"),I11,F11),I11)) -> 0.75 | N11: =IF(OR(A11="",H11="",E11=""),0,MAX(0,ROUND((H11-E11)*1440,0))) -> 0 | O11: =IF(OR(A11="",I11="",F11=""),0,MAX(0,ROUND((F11-I11)*1440,0))) -> 0 | P11: =IF(OR(L11="",M11=""),0,MAX(0,ROUND((M11-L11)*24-G11,2))) -> 9.5 | Q11: =IF(P11=0,0,MIN(P11,'00_Parametres'!$B$23)) -> 9.5 | R11: =IF(P11=0,0,MAX(0,P11-'00_Parametres'!$B$23)) -> 0
A12: 46258 | B12: EMP007 | C12: =IF(B12="","",IFERROR(VLOOKUP(B12,Employes[[ID]:[Nom Complet]],4,FALSE()),"")) -> Holé Homsala | D12: =IF(A12="","",TEXT(A12,"dddd")) -> dddd | E12: =IF(A12="","",IFERROR(INDEX('00_Parametres'!$C$7:$C$13,WEEKDAY(A12,2)),"")) -> 0.3125 | F12: =IF(A12="","",IFERROR(INDEX('00_Parametres'!$D$7:$D$13,WEEKDAY(A12,2)),"")) -> 0.75 | G12: =IF(A12="","",IFERROR(INDEX('00_Parametres'!$E$7:$E$13,WEEKDAY(A12,2)),0)) -> 1 | H12: 0.625 | I12: 0.70833333 | J12: Non | K12: Non | L12: =IF(OR(A12="",H12=""),"",IF(H12<E12,IF(OR(J12="Oui",'00_Parametres'!$B$28="Oui"),H12,E12),H12)) -> 0.625 | M12: =IF(OR(A12="",I12=""),"",IF(I12>F12,IF(OR(K12="Oui",'00_Parametres'!$B$29="Oui"),I12,F12),I12)) -> 0.70833333 | N12: =IF(OR(A12="",H12="",E12=""),0,MAX(0,ROUND((H12-E12)*1440,0))) -> 450 | O12: =IF(OR(A12="",I12="",F12=""),0,MAX(0,ROUND((F12-I12)*1440,0))) -> 60 | P12: =IF(OR(L12="",M12=""),0,MAX(0,ROUND((M12-L12)*24-G12,2))) -> 1 | Q12: =IF(P12=0,0,MIN(P12,'00_Parametres'!$B$23)) -> 1 | R12: =IF(P12=0,0,MAX(0,P12-'00_Parametres'!$B$23)) -> 0
A13: 46258 | B13: EMP008 | C13: =IF(B13="","",IFERROR(VLOOKUP(B13,Employes[[ID]:[Nom Complet]],4,FALSE()),"")) -> Ebene Ngono | D13: =IF(A13="","",TEXT(A13,"dddd")) -> dddd | E13: =IF(A13="","",IFERROR(INDEX('00_Parametres'!$C$7:$C$13,WEEKDAY(A13,2)),"")) -> 0.3125 | F13: =IF(A13="","",IFERROR(INDEX('00_Parametres'!$D$7:$D$13,WEEKDAY(A13,2)),"")) -> 0.75 | G13: =IF(A13="","",IFERROR(INDEX('00_Parametres'!$E$7:$E$13,WEEKDAY(A13,2)),0)) -> 1 | J13: Non | K13: Non | L13: =IF(OR(A13="",H13=""),"",IF(H13<E13,IF(OR(J13="Oui",'00_Parametres'!$B$28="Oui"),H13,E13),H13)) | M13: =IF(OR(A13="",I13=""),"",IF(I13>F13,IF(OR(K13="Oui",'00_Parametres'!$B$29="Oui"),I13,F13),I13)) | N13: =IF(OR(A13="",H13="",E13=""),0,MAX(0,ROUND((H13-E13)*1440,0))) -> 0 | O13: =IF(OR(A13="",I13="",F13=""),0,MAX(0,ROUND((F13-I13)*1440,0))) -> 0 | P13: =IF(OR(L13="",M13=""),0,MAX(0,ROUND((M13-L13)*24-G13,2))) -> 0 | Q13: =IF(P13=0,0,MIN(P13,'00_Parametres'!$B$23)) -> 0 | R13: =IF(P13=0,0,MAX(0,P13-'00_Parametres'!$B$23)) -> 0
A14: 46258 | B14: EMP009 | C14: =IF(B14="","",IFERROR(VLOOKUP(B14,Employes[[ID]:[Nom Complet]],4,FALSE()),"")) -> Tineba Vital Eric | D14: =IF(A14="","",TEXT(A14,"dddd")) -> dddd | E14: =IF(A14="","",IFERROR(INDEX('00_Parametres'!$C$7:$C$13,WEEKDAY(A14,2)),"")) -> 0.3125 | F14: =IF(A14="","",IFERROR(INDEX('00_Parametres'!$D$7:$D$13,WEEKDAY(A14,2)),"")) -> 0.75 | G14: =IF(A14="","",IFERROR(INDEX('00_Parametres'!$E$7:$E$13,WEEKDAY(A14,2)),0)) -> 1 | J14: Non | K14: Non | L14: =IF(OR(A14="",H14=""),"",IF(H14<E14,IF(OR(J14="Oui",'00_Parametres'!$B$28="Oui"),H14,E14),H14)) | M14: =IF(OR(A14="",I14=""),"",IF(I14>F14,IF(OR(K14="Oui",'00_Parametres'!$B$29="Oui"),I14,F14),I14)) | N14: =IF(OR(A14="",H14="",E14=""),0,MAX(0,ROUND((H14-E14)*1440,0))) -> 0 | O14: =IF(OR(A14="",I14="",F14=""),0,MAX(0,ROUND((F14-I14)*1440,0))) -> 0 | P14: =IF(OR(L14="",M14=""),0,MAX(0,ROUND((M14-L14)*24-G14,2))) -> 0 | Q14: =IF(P14=0,0,MIN(P14,'00_Parametres'!$B$23)) -> 0 | R14: =IF(P14=0,0,MAX(0,P14-'00_Parametres'!$B$23)) -> 0
A15: 46258 | B15: EMP010 | C15: =IF(B15="","",IFERROR(VLOOKUP(B15,Employes[[ID]:[Nom Complet]],4,FALSE()),"")) -> Deutchoua Tientcheu Christian | D15: =IF(A15="","",TEXT(A15,"dddd")) -> dddd | E15: =IF(A15="","",IFERROR(INDEX('00_Parametres'!$C$7:$C$13,WEEKDAY(A15,2)),"")) -> 0.3125 | F15: =IF(A15="","",IFERROR(INDEX('00_Parametres'!$D$7:$D$13,WEEKDAY(A15,2)),"")) -> 0.75 | G15: =IF(A15="","",IFERROR(INDEX('00_Parametres'!$E$7:$E$13,WEEKDAY(A15,2)),0)) -> 1 | J15: Non | K15: Non | L15: =IF(OR(A15="",H15=""),"",IF(H15<E15,IF(OR(J15="Oui",'00_Parametres'!$B$28="Oui"),H15,E15),H15)) | M15: =IF(OR(A15="",I15=""),"",IF(I15>F15,IF(OR(K15="Oui",'00_Parametres'!$B$29="Oui"),I15,F15),I15)) | N15: =IF(OR(A15="",H15="",E15=""),0,MAX(0,ROUND((H15-E15)*1440,0))) -> 0 | O15: =IF(OR(A15="",I15="",F15=""),0,MAX(0,ROUND((F15-I15)*1440,0))) -> 0 | P15: =IF(OR(L15="",M15=""),0,MAX(0,ROUND((M15-L15)*24-G15,2))) -> 0 | Q15: =IF(P15=0,0,MIN(P15,'00_Parametres'!$B$23)) -> 0 | R15: =IF(P15=0,0,MAX(0,P15-'00_Parametres'!$B$23)) -> 0
A16: 46258 | B16: EMP011 | C16: =IF(B16="","",IFERROR(VLOOKUP(B16,Employes[[ID]:[Nom Complet]],4,FALSE()),"")) -> Fouakouet Youssoufa | D16: =IF(A16="","",TEXT(A16,"dddd")) -> dddd | E16: =IF(A16="","",IFERROR(INDEX('00_Parametres'!$C$7:$C$13,WEEKDAY(A16,2)),"")) -> 0.3125 | F16: =IF(A16="","",IFERROR(INDEX('00_Parametres'!$D$7:$D$13,WEEKDAY(A16,2)),"")) -> 0.75 | G16: =IF(A16="","",IFERROR(INDEX('00_Parametres'!$E$7:$E$13,WEEKDAY(A16,2)),0)) -> 1 | J16: Non | K16: Non | L16: =IF(OR(A16="",H16=""),"",IF(H16<E16,IF(OR(J16="Oui",'00_Parametres'!$B$28="Oui"),H16,E16),H16)) | M16: =IF(OR(A16="",I16=""),"",IF(I16>F16,IF(OR(K16="Oui",'00_Parametres'!$B$29="Oui"),I16,F16),I16)) | N16: =IF(OR(A16="",H16="",E16=""),0,MAX(0,ROUND((H16-E16)*1440,0))) -> 0 | O16: =IF(OR(A16="",I16="",F16=""),0,MAX(0,ROUND((F16-I16)*1440,0))) -> 0 | P16: =IF(OR(L16="",M16=""),0,MAX(0,ROUND((M16-L16)*24-G16,2))) -> 0 | Q16: =IF(P16=0,0,MIN(P16,'00_Parametres'!$B$23)) -> 0 | R16: =IF(P16=0,0,MAX(0,P16-'00_Parametres'!$B$23)) -> 0
A17: 46258 | B17: EMP012 | C17: =IF(B17="","",IFERROR(VLOOKUP(B17,Employes[[ID]:[Nom Complet]],4,FALSE()),"")) -> Ngouamera Adrien Gildas | D17: =IF(A17="","",TEXT(A17,"dddd")) -> dddd | E17: =IF(A17="","",IFERROR(INDEX('00_Parametres'!$C$7:$C$13,WEEKDAY(A17,2)),"")) -> 0.3125 | F17: =IF(A17="","",IFERROR(INDEX('00_Parametres'!$D$7:$D$13,WEEKDAY(A17,2)),"")) -> 0.75 | G17: =IF(A17="","",IFERROR(INDEX('00_Parametres'!$E$7:$E$13,WEEKDAY(A17,2)),0)) -> 1 | J17: Non | K17: Non | L17: =IF(OR(A17="",H17=""),"",IF(H17<E17,IF(OR(J17="Oui",'00_Parametres'!$B$28="Oui"),H17,E17),H17)) | M17: =IF(OR(A17="",I17=""),"",IF(I17>F17,IF(OR(K17="Oui",'00_Parametres'!$B$29="Oui"),I17,F17),I17)) | N17: =IF(OR(A17="",H17="",E17=""),0,MAX(0,ROUND((H17-E17)*1440,0))) -> 0 | O17: =IF(OR(A17="",I17="",F17=""),0,MAX(0,ROUND((F17-I17)*1440,0))) -> 0 | P17: =IF(OR(L17="",M17=""),0,MAX(0,ROUND((M17-L17)*24-G17,2))) -> 0 | Q17: =IF(P17=0,0,MIN(P17,'00_Parametres'!$B$23)) -> 0 | R17: =IF(P17=0,0,MAX(0,P17-'00_Parametres'!$B$23)) -> 0
A18: 46258 | B18: EMP013 | C18: =IF(B18="","",IFERROR(VLOOKUP(B18,Employes[[ID]:[Nom Complet]],4,FALSE()),"")) -> Nague Zemdjui Arnaud | D18: =IF(A18="","",TEXT(A18,"dddd")) -> dddd | E18: =IF(A18="","",IFERROR(INDEX('00_Parametres'!$C$7:$C$13,WEEKDAY(A18,2)),"")) -> 0.3125 | F18: =IF(A18="","",IFERROR(INDEX('00_Parametres'!$D$7:$D$13,WEEKDAY(A18,2)),"")) -> 0.75 | G18: =IF(A18="","",IFERROR(INDEX('00_Parametres'!$E$7:$E$13,WEEKDAY(A18,2)),0)) -> 1 | J18: Non | K18: Non | L18: =IF(OR(A18="",H18=""),"",IF(H18<E18,IF(OR(J18="Oui",'00_Parametres'!$B$28="Oui"),H18,E18),H18)) | M18: =IF(OR(A18="",I18=""),"",IF(I18>F18,IF(OR(K18="Oui",'00_Parametres'!$B$29="Oui"),I18,F18),I18)) | N18: =IF(OR(A18="",H18="",E18=""),0,MAX(0,ROUND((H18-E18)*1440,0))) -> 0 | O18: =IF(OR(A18="",I18="",F18=""),0,MAX(0,ROUND((F18-I18)*1440,0))) -> 0 | P18: =IF(OR(L18="",M18=""),0,MAX(0,ROUND((M18-L18)*24-G18,2))) -> 0 | Q18: =IF(P18=0,0,MIN(P18,'00_Parametres'!$B$23)) -> 0 | R18: =IF(P18=0,0,MAX(0,P18-'00_Parametres'!$B$23)) -> 0
C19: =IF(B19="","",IFERROR(VLOOKUP(B19,Employes[[ID]:[Nom Complet]],4,FALSE()),"")) | D19: =IF(A19="","",TEXT(A19,"dddd")) | E19: =IF(A19="","",IFERROR(INDEX('00_Parametres'!$C$7:$C$13,WEEKDAY(A19,2)),"")) | F19: =IF(A19="","",IFERROR(INDEX('00_Parametres'!$D$7:$D$13,WEEKDAY(A19,2)),"")) | G19: =IF(A19="","",IFERROR(INDEX('00_Parametres'!$E$7:$E$13,WEEKDAY(A19,2)),0)) | J19: Non | K19: Non | L19: =IF(OR(A19="",H19=""),"",IF(H19<E19,IF(OR(J19="Oui",'00_Parametres'!$B$28="Oui"),H19,E19),H19)) | M19: =IF(OR(A19="",I19=""),"",IF(I19>F19,IF(OR(K19="Oui",'00_Parametres'!$B$29="Oui"),I19,F19),I19)) | N19: =IF(OR(A19="",H19="",E19=""),0,MAX(0,ROUND((H19-E19)*1440,0))) -> 0 | O19: =IF(OR(A19="",I19="",F19=""),0,MAX(0,ROUND((F19-I19)*1440,0))) -> 0 | P19: =IF(OR(L19="",M19=""),0,MAX(0,ROUND((M19-L19)*24-G19,2))) -> 0 | Q19: =IF(P19=0,0,MIN(P19,'00_Parametres'!$B$23)) -> 0 | R19: =IF(P19=0,0,MAX(0,P19-'00_Parametres'!$B$23)) -> 0
A20: 46259 | B20: EMP001 | C20: =IF(B20="","",IFERROR(VLOOKUP(B20,Employes[[ID]:[Nom Complet]],4,FALSE()),"")) -> Tsafack Ndongmo Symphonien | D20: =IF(A20="","",TEXT(A20,"dddd")) -> dddd | E20: =IF(A20="","",IFERROR(INDEX('00_Parametres'!$C$7:$C$13,WEEKDAY(A20,2)),"")) -> 0.3125 | F20: =IF(A20="","",IFERROR(INDEX('00_Parametres'!$D$7:$D$13,WEEKDAY(A20,2)),"")) -> 0.75 | G20: =IF(A20="","",IFERROR(INDEX('00_Parametres'!$E$7:$E$13,WEEKDAY(A20,2)),0)) -> 1 | H20: 0.40277778 | I20: 0.83333333 | J20: Non | K20: Non | L20: =IF(OR(A20="",H20=""),"",IF(H20<E20,IF(OR(J20="Oui",'00_Parametres'!$B$28="Oui"),H20,E20),H20)) -> 0.40277778 | M20: =IF(OR(A20="",I20=""),"",IF(I20>F20,IF(OR(K20="Oui",'00_Parametres'!$B$29="Oui"),I20,F20),I20)) -> 0.75 | N20: =IF(OR(A20="",H20="",E20=""),0,MAX(0,ROUND((H20-E20)*1440,0))) -> 130 | O20: =IF(OR(A20="",I20="",F20=""),0,MAX(0,ROUND((F20-I20)*1440,0))) -> 0 | P20: =IF(OR(L20="",M20=""),0,MAX(0,ROUND((M20-L20)*24-G20,2))) -> 7.33 | Q20: =IF(P20=0,0,MIN(P20,'00_Parametres'!$B$23)) -> 7.33 | R20: =IF(P20=0,0,MAX(0,P20-'00_Parametres'!$B$23)) -> 0
A21: 46259 | B21: EMP002 | C21: =IF(B21="","",IFERROR(VLOOKUP(B21,Employes[[ID]:[Nom Complet]],4,FALSE()),"")) -> Pandja Tchatchoua Syriane | D21: =IF(A21="","",TEXT(A21,"dddd")) -> dddd | E21: =IF(A21="","",IFERROR(INDEX('00_Parametres'!$C$7:$C$13,WEEKDAY(A21,2)),"")) -> 0.3125 | F21: =IF(A21="","",IFERROR(INDEX('00_Parametres'!$D$7:$D$13,WEEKDAY(A21,2)),"")) -> 0.75 | G21: =IF(A21="","",IFERROR(INDEX('00_Parametres'!$E$7:$E$13,WEEKDAY(A21,2)),0)) -> 1 | H21: 0.47916667 | I21: 0.75 | J21: Non | K21: Non | L21: =IF(OR(A21="",H21=""),"",IF(H21<E21,IF(OR(J21="Oui",'00_Parametres'!$B$28="Oui"),H21,E21),H21)) -> 0.47916667 | M21: =IF(OR(A21="",I21=""),"",IF(I21>F21,IF(OR(K21="Oui",'00_Parametres'!$B$29="Oui"),I21,F21),I21)) -> 0.75 | N21: =IF(OR(A21="",H21="",E21=""),0,MAX(0,ROUND((H21-E21)*1440,0))) -> 240 | O21: =IF(OR(A21="",I21="",F21=""),0,MAX(0,ROUND((F21-I21)*1440,0))) -> 0 | P21: =IF(OR(L21="",M21=""),0,MAX(0,ROUND((M21-L21)*24-G21,2))) -> 5.5 | Q21: =IF(P21=0,0,MIN(P21,'00_Parametres'!$B$23)) -> 5.5 | R21: =IF(P21=0,0,MAX(0,P21-'00_Parametres'!$B$23)) -> 0
A22: 46259 | B22: EMP003 | C22: =IF(B22="","",IFERROR(VLOOKUP(B22,Employes[[ID]:[Nom Complet]],4,FALSE()),"")) -> Takoueta Yvan | D22: =IF(A22="","",TEXT(A22,"dddd")) -> dddd | E22: =IF(A22="","",IFERROR(INDEX('00_Parametres'!$C$7:$C$13,WEEKDAY(A22,2)),"")) -> 0.3125 | F22: =IF(A22="","",IFERROR(INDEX('00_Parametres'!$D$7:$D$13,WEEKDAY(A22,2)),"")) -> 0.75 | G22: =IF(A22="","",IFERROR(INDEX('00_Parametres'!$E$7:$E$13,WEEKDAY(A22,2)),0)) -> 1 | H22: 0.375 | I22: 0.85416667 | J22: Non | K22: Non | L22: =IF(OR(A22="",H22=""),"",IF(H22<E22,IF(OR(J22="Oui",'00_Parametres'!$B$28="Oui"),H22,E22),H22)) -> 0.375 | M22: =IF(OR(A22="",I22=""),"",IF(I22>F22,IF(OR(K22="Oui",'00_Parametres'!$B$29="Oui"),I22,F22),I22)) -> 0.75 | N22: =IF(OR(A22="",H22="",E22=""),0,MAX(0,ROUND((H22-E22)*1440,0))) -> 90 | O22: =IF(OR(A22="",I22="",F22=""),0,MAX(0,ROUND((F22-I22)*1440,0))) -> 0 | P22: =IF(OR(L22="",M22=""),0,MAX(0,ROUND((M22-L22)*24-G22,2))) -> 8 | Q22: =IF(P22=0,0,MIN(P22,'00_Parametres'!$B$23)) -> 8 | R22: =IF(P22=0,0,MAX(0,P22-'00_Parametres'!$B$23)) -> 0
A23: 46259 | B23: EMP004 | C23: =IF(B23="","",IFERROR(VLOOKUP(B23,Employes[[ID]:[Nom Complet]],4,FALSE()),"")) -> Chekep Faustin | D23: =IF(A23="","",TEXT(A23,"dddd")) -> dddd | E23: =IF(A23="","",IFERROR(INDEX('00_Parametres'!$C$7:$C$13,WEEKDAY(A23,2)),"")) -> 0.3125 | F23: =IF(A23="","",IFERROR(INDEX('00_Parametres'!$D$7:$D$13,WEEKDAY(A23,2)),"")) -> 0.75 | G23: =IF(A23="","",IFERROR(INDEX('00_Parametres'!$E$7:$E$13,WEEKDAY(A23,2)),0)) -> 1 | H23: 0.33541667 | I23: 0.79166667 | J23: Non | K23: Non | L23: =IF(OR(A23="",H23=""),"",IF(H23<E23,IF(OR(J23="Oui",'00_Parametres'!$B$28="Oui"),H23,E23),H23)) -> 0.33541667 | M23: =IF(OR(A23="",I23=""),"",IF(I23>F23,IF(OR(K23="Oui",'00_Parametres'!$B$29="Oui"),I23,F23),I23)) -> 0.75 | N23: =IF(OR(A23="",H23="",E23=""),0,MAX(0,ROUND((H23-E23)*1440,0))) -> 33 | O23: =IF(OR(A23="",I23="",F23=""),0,MAX(0,ROUND((F23-I23)*1440,0))) -> 0 | P23: =IF(OR(L23="",M23=""),0,MAX(0,ROUND((M23-L23)*24-G23,2))) -> 8.95 | Q23: =IF(P23=0,0,MIN(P23,'00_Parametres'!$B$23)) -> 8.95 | R23: =IF(P23=0,0,MAX(0,P23-'00_Parametres'!$B$23)) -> 0
A24: 46259 | B24: EMP005 | C24: =IF(B24="","",IFERROR(VLOOKUP(B24,Employes[[ID]:[Nom Complet]],4,FALSE()),"")) -> Abdou | D24: =IF(A24="","",TEXT(A24,"dddd")) -> dddd | E24: =IF(A24="","",IFERROR(INDEX('00_Parametres'!$C$7:$C$13,WEEKDAY(A24,2)),"")) -> 0.3125 | F24: =IF(A24="","",IFERROR(INDEX('00_Parametres'!$D$7:$D$13,WEEKDAY(A24,2)),"")) -> 0.75 | G24: =IF(A24="","",IFERROR(INDEX('00_Parametres'!$E$7:$E$13,WEEKDAY(A24,2)),0)) -> 1 | H24: 0.33333333 | I24: 0.79166667 | J24: Non | K24: Non | L24: =IF(OR(A24="",H24=""),"",IF(H24<E24,IF(OR(J24="Oui",'00_Parametres'!$B$28="Oui"),H24,E24),H24)) -> 0.33333333 | M24: =IF(OR(A24="",I24=""),"",IF(I24>F24,IF(OR(K24="Oui",'00_Parametres'!$B$29="Oui"),I24,F24),I24)) -> 0.75 | N24: =IF(OR(A24="",H24="",E24=""),0,MAX(0,ROUND((H24-E24)*1440,0))) -> 30 | O24: =IF(OR(A24="",I24="",F24=""),0,MAX(0,ROUND((F24-I24)*1440,0))) -> 0 | P24: =IF(OR(L24="",M24=""),0,MAX(0,ROUND((M24-L24)*24-G24,2))) -> 9 | Q24: =IF(P24=0,0,MIN(P24,'00_Parametres'!$B$23)) -> 9 | R24: =IF(P24=0,0,MAX(0,P24-'00_Parametres'!$B$23)) -> 0
A25: 46259 | B25: EMP006 | C25: =IF(B25="","",IFERROR(VLOOKUP(B25,Employes[[ID]:[Nom Complet]],4,FALSE()),"")) -> Nyontyen Si Jean Vinny | D25: =IF(A25="","",TEXT(A25,"dddd")) -> dddd | E25: =IF(A25="","",IFERROR(INDEX('00_Parametres'!$C$7:$C$13,WEEKDAY(A25,2)),"")) -> 0.3125 | F25: =IF(A25="","",IFERROR(INDEX('00_Parametres'!$D$7:$D$13,WEEKDAY(A25,2)),"")) -> 0.75 | G25: =IF(A25="","",IFERROR(INDEX('00_Parametres'!$E$7:$E$13,WEEKDAY(A25,2)),0)) -> 1 | H25: 0.34791667 | I25: 0.75 | J25: Non | K25: Non | L25: =IF(OR(A25="",H25=""),"",IF(H25<E25,IF(OR(J25="Oui",'00_Parametres'!$B$28="Oui"),H25,E25),H25)) -> 0.34791667 | M25: =IF(OR(A25="",I25=""),"",IF(I25>F25,IF(OR(K25="Oui",'00_Parametres'!$B$29="Oui"),I25,F25),I25)) -> 0.75 | N25: =IF(OR(A25="",H25="",E25=""),0,MAX(0,ROUND((H25-E25)*1440,0))) -> 51 | O25: =IF(OR(A25="",I25="",F25=""),0,MAX(0,ROUND((F25-I25)*1440,0))) -> 0 | P25: =IF(OR(L25="",M25=""),0,MAX(0,ROUND((M25-L25)*24-G25,2))) -> 8.65 | Q25: =IF(P25=0,0,MIN(P25,'00_Parametres'!$B$23)) -> 8.65 | R25: =IF(P25=0,0,MAX(0,P25-'00_Parametres'!$B$23)) -> 0
A26: 46259 | B26: EMP007 | C26: =IF(B26="","",IFERROR(VLOOKUP(B26,Employes[[ID]:[Nom Complet]],4,FALSE()),"")) -> Holé Homsala | D26: =IF(A26="","",TEXT(A26,"dddd")) -> dddd | E26: =IF(A26="","",IFERROR(INDEX('00_Parametres'!$C$7:$C$13,WEEKDAY(A26,2)),"")) -> 0.3125 | F26: =IF(A26="","",IFERROR(INDEX('00_Parametres'!$D$7:$D$13,WEEKDAY(A26,2)),"")) -> 0.75 | G26: =IF(A26="","",IFERROR(INDEX('00_Parametres'!$E$7:$E$13,WEEKDAY(A26,2)),0)) -> 1 | H26: 0.35694444 | I26: 0.79166667 | J26: Non | K26: Non | L26: =IF(OR(A26="",H26=""),"",IF(H26<E26,IF(OR(J26="Oui",'00_Parametres'!$B$28="Oui"),H26,E26),H26)) -> 0.35694444 | M26: =IF(OR(A26="",I26=""),"",IF(I26>F26,IF(OR(K26="Oui",'00_Parametres'!$B$29="Oui"),I26,F26),I26)) -> 0.75 | N26: =IF(OR(A26="",H26="",E26=""),0,MAX(0,ROUND((H26-E26)*1440,0))) -> 64 | O26: =IF(OR(A26="",I26="",F26=""),0,MAX(0,ROUND((F26-I26)*1440,0))) -> 0 | P26: =IF(OR(L26="",M26=""),0,MAX(0,ROUND((M26-L26)*24-G26,2))) -> 8.43 | Q26: =IF(P26=0,0,MIN(P26,'00_Parametres'!$B$23)) -> 8.43 | R26: =IF(P26=0,0,MAX(0,P26-'00_Parametres'!$B$23)) -> 0
A27: 46259 | B27: EMP008 | C27: =IF(B27="","",IFERROR(VLOOKUP(B27,Employes[[ID]:[Nom Complet]],4,FALSE()),"")) -> Ebene Ngono | D27: =IF(A27="","",TEXT(A27,"dddd")) -> dddd | E27: =IF(A27="","",IFERROR(INDEX('00_Parametres'!$C$7:$C$13,WEEKDAY(A27,2)),"")) -> 0.3125 | F27: =IF(A27="","",IFERROR(INDEX('00_Parametres'!$D$7:$D$13,WEEKDAY(A27,2)),"")) -> 0.75 | G27: =IF(A27="","",IFERROR(INDEX('00_Parametres'!$E$7:$E$13,WEEKDAY(A27,2)),0)) -> 1 | H27: 0.31944444 | I27: 0.79166667 | J27: Non | K27: Non | L27: =IF(OR(A27="",H27=""),"",IF(H27<E27,IF(OR(J27="Oui",'00_Parametres'!$B$28="Oui"),H27,E27),H27)) -> 0.31944444 | M27: =IF(OR(A27="",I27=""),"",IF(I27>F27,IF(OR(K27="Oui",'00_Parametres'!$B$29="Oui"),I27,F27),I27)) -> 0.75 | N27: =IF(OR(A27="",H27="",E27=""),0,MAX(0,ROUND((H27-E27)*1440,0))) -> 10 | O27: =IF(OR(A27="",I27="",F27=""),0,MAX(0,ROUND((F27-I27)*1440,0))) -> 0 | P27: =IF(OR(L27="",M27=""),0,MAX(0,ROUND((M27-L27)*24-G27,2))) -> 9.33 | Q27: =IF(P27=0,0,MIN(P27,'00_Parametres'!$B$23)) -> 9.33 | R27: =IF(P27=0,0,MAX(0,P27-'00_Parametres'!$B$23)) -> 0
A28: 46259 | B28: EMP009 | C28: =IF(B28="","",IFERROR(VLOOKUP(B28,Employes[[ID]:[Nom Complet]],4,FALSE()),"")) -> Tineba Vital Eric | D28: =IF(A28="","",TEXT(A28,"dddd")) -> dddd | E28: =IF(A28="","",IFERROR(INDEX('00_Parametres'!$C$7:$C$13,WEEKDAY(A28,2)),"")) -> 0.3125 | F28: =IF(A28="","",IFERROR(INDEX('00_Parametres'!$D$7:$D$13,WEEKDAY(A28,2)),"")) -> 0.75 | G28: =IF(A28="","",IFERROR(INDEX('00_Parametres'!$E$7:$E$13,WEEKDAY(A28,2)),0)) -> 1 | H28: 0.34375 | I28: 0.79166667 | J28: Non | K28: Non | L28: =IF(OR(A28="",H28=""),"",IF(H28<E28,IF(OR(J28="Oui",'00_Parametres'!$B$28="Oui"),H28,E28),H28)) -> 0.34375 | M28: =IF(OR(A28="",I28=""),"",IF(I28>F28,IF(OR(K28="Oui",'00_Parametres'!$B$29="Oui"),I28,F28),I28)) -> 0.75 | N28: =IF(OR(A28="",H28="",E28=""),0,MAX(0,ROUND((H28-E28)*1440,0))) -> 45 | O28: =IF(OR(A28="",I28="",F28=""),0,MAX(0,ROUND((F28-I28)*1440,0))) -> 0 | P28: =IF(OR(L28="",M28=""),0,MAX(0,ROUND((M28-L28)*24-G28,2))) -> 8.75 | Q28: =IF(P28=0,0,MIN(P28,'00_Parametres'!$B$23)) -> 8.75 | R28: =IF(P28=0,0,MAX(0,P28-'00_Parametres'!$B$23)) -> 0
A29: 46259 | B29: EMP010 | C29: =IF(B29="","",IFERROR(VLOOKUP(B29,Employes[[ID]:[Nom Complet]],4,FALSE()),"")) -> Deutchoua Tientcheu Christian | D29: =IF(A29="","",TEXT(A29,"dddd")) -> dddd | E29: =IF(A29="","",IFERROR(INDEX('00_Parametres'!$C$7:$C$13,WEEKDAY(A29,2)),"")) -> 0.3125 | F29: =IF(A29="","",IFERROR(INDEX('00_Parametres'!$D$7:$D$13,WEEKDAY(A29,2)),"")) -> 0.75 | G29: =IF(A29="","",IFERROR(INDEX('00_Parametres'!$E$7:$E$13,WEEKDAY(A29,2)),0)) -> 1 | H29: 0.5 | I29: 0.8125 | J29: Non | K29: Non | L29: =IF(OR(A29="",H29=""),"",IF(H29<E29,IF(OR(J29="Oui",'00_Parametres'!$B$28="Oui"),H29,E29),H29)) -> 0.5 | M29: =IF(OR(A29="",I29=""),"",IF(I29>F29,IF(OR(K29="Oui",'00_Parametres'!$B$29="Oui"),I29,F29),I29)) -> 0.75 | N29: =IF(OR(A29="",H29="",E29=""),0,MAX(0,ROUND((H29-E29)*1440,0))) -> 270 | O29: =IF(OR(A29="",I29="",F29=""),0,MAX(0,ROUND((F29-I29)*1440,0))) -> 0 | P29: =IF(OR(L29="",M29=""),0,MAX(0,ROUND((M29-L29)*24-G29,2))) -> 5 | Q29: =IF(P29=0,0,MIN(P29,'00_Parametres'!$B$23)) -> 5 | R29: =IF(P29=0,0,MAX(0,P29-'00_Parametres'!$B$23)) -> 0
A30: 46259 | B30: EMP011 | C30: =IF(B30="","",IFERROR(VLOOKUP(B30,Employes[[ID]:[Nom Complet]],4,FALSE()),"")) -> Fouakouet Youssoufa | D30: =IF(A30="","",TEXT(A30,"dddd")) -> dddd | E30: =IF(A30="","",IFERROR(INDEX('00_Parametres'!$C$7:$C$13,WEEKDAY(A30,2)),"")) -> 0.3125 | F30: =IF(A30="","",IFERROR(INDEX('00_Parametres'!$D$7:$D$13,WEEKDAY(A30,2)),"")) -> 0.75 | G30: =IF(A30="","",IFERROR(INDEX('00_Parametres'!$E$7:$E$13,WEEKDAY(A30,2)),0)) -> 1 | H30: 0.41666667 | I30: 0.75 | J30: Non | K30: Non | L30: =IF(OR(A30="",H30=""),"",IF(H30<E30,IF(OR(J30="Oui",'00_Parametres'!$B$28="Oui"),H30,E30),H30)) -> 0.41666667 | M30: =IF(OR(A30="",I30=""),"",IF(I30>F30,IF(OR(K30="Oui",'00_Parametres'!$B$29="Oui"),I30,F30),I30)) -> 0.75 | N30: =IF(OR(A30="",H30="",E30=""),0,MAX(0,ROUND((H30-E30)*1440,0))) -> 150 | O30: =IF(OR(A30="",I30="",F30=""),0,MAX(0,ROUND((F30-I30)*1440,0))) -> 0 | P30: =IF(OR(L30="",M30=""),0,MAX(0,ROUND((M30-L30)*24-G30,2))) -> 7 | Q30: =IF(P30=0,0,MIN(P30,'00_Parametres'!$B$23)) -> 7 | R30: =IF(P30=0,0,MAX(0,P30-'00_Parametres'!$B$23)) -> 0
A31: 46259 | B31: EMP012 | C31: =IF(B31="","",IFERROR(VLOOKUP(B31,Employes[[ID]:[Nom Complet]],4,FALSE()),"")) -> Ngouamera Adrien Gildas | D31: =IF(A31="","",TEXT(A31,"dddd")) -> dddd | E31: =IF(A31="","",IFERROR(INDEX('00_Parametres'!$C$7:$C$13,WEEKDAY(A31,2)),"")) -> 0.3125 | F31: =IF(A31="","",IFERROR(INDEX('00_Parametres'!$D$7:$D$13,WEEKDAY(A31,2)),"")) -> 0.75 | G31: =IF(A31="","",IFERROR(INDEX('00_Parametres'!$E$7:$E$13,WEEKDAY(A31,2)),0)) -> 1 | H31: 0.33611111 | I31: 0.79166667 | J31: Non | K31: Non | L31: =IF(OR(A31="",H31=""),"",IF(H31<E31,IF(OR(J31="Oui",'00_Parametres'!$B$28="Oui"),H31,E31),H31)) -> 0.33611111 | M31: =IF(OR(A31="",I31=""),"",IF(I31>F31,IF(OR(K31="Oui",'00_Parametres'!$B$29="Oui"),I31,F31),I31)) -> 0.75 | N31: =IF(OR(A31="",H31="",E31=""),0,MAX(0,ROUND((H31-E31)*1440,0))) -> 34 | O31: =IF(OR(A31="",I31="",F31=""),0,MAX(0,ROUND((F31-I31)*1440,0))) -> 0 | P31: =IF(OR(L31="",M31=""),0,MAX(0,ROUND((M31-L31)*24-G31,2))) -> 8.93 | Q31: =IF(P31=0,0,MIN(P31,'00_Parametres'!$B$23)) -> 8.93 | R31: =IF(P31=0,0,MAX(0,P31-'00_Parametres'!$B$23)) -> 0
... A33: 46259 | B33: EMP014 | C33: =IF(B33="","",IFERROR(VLOOKUP(B33,Employes[[ID]:[Nom Complet]],4,FALSE()),"")) -> Zo'o Mbarga Jean Loic | D33: =IF(A33="","",TEXT(A33,"dddd")) -> dddd | E33: =IF(A33="","",IFERROR(INDEX('00_Parametres'!$C$7:$C$13,WEEKDAY(A33,2)),"")) -> 0.3125 | F33: =IF(A33="","",IFERROR(INDEX('00_Parametres'!$D$7:$D$13,WEEKDAY(A33,2)),"")) -> 0.75 | G33: =IF(A33="","",IFERROR(INDEX('00_Parametres'!$E$7:$E$13,WEEKDAY(A33,2)),0)) -> 1 | H33: 0.33333333 | I33: 0.75 | J33: Non | K33: Non | L33: =IF(OR(A33="",H33=""),"",IF(H33<E33,IF(OR(J33="Oui",'00_Parametres'!$B$28="Oui"),H33,E33),H33)) -> 0.33333333 | M33: =IF(OR(A33="",I33=""),"",IF(I33>F33,IF(OR(K33="Oui",'00_Parametres'!$B$29="Oui"),I33,F33),I33)) -> 0.75 | N33: =IF(OR(A33="",H33="",E33=""),0,MAX(0,ROUND((H33-E33)*1440,0))) -> 30 | O33: =IF(OR(A33="",I33="",F33=""),0,MAX(0,ROUND((F33-I33)*1440,0))) -> 0 | P33: =IF(OR(L33="",M33=""),0,MAX(0,ROUND((M33-L33)*24-G33,2))) -> 9 | Q33: =IF(P33=0,0,MIN(P33,'00_Parametres'!$B$23)) -> 9 | R33: =IF(P33=0,0,MAX(0,P33-'00_Parametres'!$B$23)) -> 0
C34: =IF(B34="","",IFERROR(VLOOKUP(B34,Employes[[ID]:[Nom Complet]],4,FALSE()),"")) | D34: =IF(A34="","",TEXT(A34,"dddd")) | E34: =IF(A34="","",IFERROR(INDEX('00_Parametres'!$C$7:$C$13,WEEKDAY(A34,2)),"")) | F34: =IF(A34="","",IFERROR(INDEX('00_Parametres'!$D$7:$D$13,WEEKDAY(A34,2)),"")) | G34: =IF(A34="","",IFERROR(INDEX('00_Parametres'!$E$7:$E$13,WEEKDAY(A34,2)),0)) | J34: Non | K34: Non | L34: =IF(OR(A34="",H34=""),"",IF(H34<E34,IF(OR(J34="Oui",'00_Parametres'!$B$28="Oui"),H34,E34),H34)) | M34: =IF(OR(A34="",I34=""),"",IF(I34>F34,IF(OR(K34="Oui",'00_Parametres'!$B$29="Oui"),I34,F34),I34)) | N34: =IF(OR(A34="",H34="",E34=""),0,MAX(0,ROUND((H34-E34)*1440,0))) -> 0 | O34: =IF(OR(A34="",I34="",F34=""),0,MAX(0,ROUND((F34-I34)*1440,0))) -> 0 | P34: =IF(OR(L34="",M34=""),0,MAX(0,ROUND((M34-L34)*24-G34,2))) -> 0 | Q34: =IF(P34=0,0,MIN(P34,'00_Parametres'!$B$23)) -> 0 | R34: =IF(P34=0,0,MAX(0,P34-'00_Parametres'!$B$23)) -> 0
A35: 46260 | B35: EMP001 | C35: =IF(B35="","",IFERROR(VLOOKUP(B35,Employes[[ID]:[Nom Complet]],4,FALSE()),"")) -> Tsafack Ndongmo Symphonien | D35: =IF(A35="","",TEXT(A35,"dddd")) -> 8/262026 | E35: =IF(A35="","",IFERROR(INDEX('00_Parametres'!$C$7:$C$13,WEEKDAY(A35,2)),"")) | F35: =IF(A35="","",IFERROR(INDEX('00_Parametres'!$D$7:$D$13,WEEKDAY(A35,2)),"")) | G35: =IF(A35="","",IFERROR(INDEX('00_Parametres'!$E$7:$E$13,WEEKDAY(A35,2)),0)) -> 0 | H35: 0.3125 | J35: Non | K35: Non | L35: =IF(OR(A35="",H35=""),"",IF(H35<E35,IF(OR(J35="Oui",'00_Parametres'!$B$28="Oui"),H35,E35),H35)) | M35: =IF(OR(A35="",I35=""),"",IF(I35>F35,IF(OR(K35="Oui",'00_Parametres'!$B$29="Oui"),I35,F35),I35)) | N35: =IF(OR(A35="",H35="",E35=""),0,MAX(0,ROUND((H35-E35)*1440,0))) -> 0 | O35: =IF(OR(A35="",I35="",F35=""),0,MAX(0,ROUND((F35-I35)*1440,0))) -> 0 | P35: =IF(OR(L35="",M35=""),0,MAX(0,ROUND((M35-L35)*24-G35,2))) -> 0 | Q35: =IF(P35=0,0,MIN(P35,'00_Parametres'!$B$23)) -> 0 | R35: =IF(P35=0,0,MAX(0,P35-'00_Parametres'!$B$23)) -> 0
A36: 46260 | B36: EMP002 | C36: =IF(B36="","",IFERROR(VLOOKUP(B36,Employes[[ID]:[Nom Complet]],4,FALSE()),"")) -> Pandja Tchatchoua Syriane | D36: =IF(A36="","",TEXT(A36,"dddd")) -> 8/262026 | E36: =IF(A36="","",IFERROR(INDEX('00_Parametres'!$C$7:$C$13,WEEKDAY(A36,2)),"")) | F36: =IF(A36="","",IFERROR(INDEX('00_Parametres'!$D$7:$D$13,WEEKDAY(A36,2)),"")) | G36: =IF(A36="","",IFERROR(INDEX('00_Parametres'!$E$7:$E$13,WEEKDAY(A36,2)),0)) -> 0 | H36: 0.36805556 | J36: Non | K36: Non | L36: =IF(OR(A36="",H36=""),"",IF(H36<E36,IF(OR(J36="Oui",'00_Parametres'!$B$28="Oui"),H36,E36),H36)) | M36: =IF(OR(A36="",I36=""),"",IF(I36>F36,IF(OR(K36="Oui",'00_Parametres'!$B$29="Oui"),I36,F36),I36)) | N36: =IF(OR(A36="",H36="",E36=""),0,MAX(0,ROUND((H36-E36)*1440,0))) -> 0 | O36: =IF(OR(A36="",I36="",F36=""),0,MAX(0,ROUND((F36-I36)*1440,0))) -> 0 | P36: =IF(OR(L36="",M36=""),0,MAX(0,ROUND((M36-L36)*24-G36,2))) -> 0 | Q36: =IF(P36=0,0,MIN(P36,'00_Parametres'!$B$23)) -> 0 | R36: =IF(P36=0,0,MAX(0,P36-'00_Parametres'!$B$23)) -> 0
A37: 46260 | B37: EMP003 | C37: =IF(B37="","",IFERROR(VLOOKUP(B37,Employes[[ID]:[Nom Complet]],4,FALSE()),"")) -> Takoueta Yvan | D37: =IF(A37="","",TEXT(A37,"dddd")) -> 8/262026 | E37: =IF(A37="","",IFERROR(INDEX('00_Parametres'!$C$7:$C$13,WEEKDAY(A37,2)),"")) | F37: =IF(A37="","",IFERROR(INDEX('00_Parametres'!$D$7:$D$13,WEEKDAY(A37,2)),"")) | G37: =IF(A37="","",IFERROR(INDEX('00_Parametres'!$E$7:$E$13,WEEKDAY(A37,2)),0)) -> 0 | H37: 0.33333333 | J37: Non | K37: Non | L37: =IF(OR(A37="",H37=""),"",IF(H37<E37,IF(OR(J37="Oui",'00_Parametres'!$B$28="Oui"),H37,E37),H37)) | M37: =IF(OR(A37="",I37=""),"",IF(I37>F37,IF(OR(K37="Oui",'00_Parametres'!$B$29="Oui"),I37,F37),I37)) | N37: =IF(OR(A37="",H37="",E37=""),0,MAX(0,ROUND((H37-E37)*1440,0))) -> 0 | O37: =IF(OR(A37="",I37="",F37=""),0,MAX(0,ROUND((F37-I37)*1440,0))) -> 0 | P37: =IF(OR(L37="",M37=""),0,MAX(0,ROUND((M37-L37)*24-G37,2))) -> 0 | Q37: =IF(P37=0,0,MIN(P37,'00_Parametres'!$B$23)) -> 0 | R37: =IF(P37=0,0,MAX(0,P37-'00_Parametres'!$B$23)) -> 0
A38: 46260 | B38: EMP004 | C38: =IF(B38="","",IFERROR(VLOOKUP(B38,Employes[[ID]:[Nom Complet]],4,FALSE()),"")) -> Chekep Faustin | D38: =IF(A38="","",TEXT(A38,"dddd")) -> 8/262026 | E38: =IF(A38="","",IFERROR(INDEX('00_Parametres'!$C$7:$C$13,WEEKDAY(A38,2)),"")) | F38: =IF(A38="","",IFERROR(INDEX('00_Parametres'!$D$7:$D$13,WEEKDAY(A38,2)),"")) | G38: =IF(A38="","",IFERROR(INDEX('00_Parametres'!$E$7:$E$13,WEEKDAY(A38,2)),0)) -> 0 | H38: 0.3125 | J38: Non | K38: Non | L38: =IF(OR(A38="",H38=""),"",IF(H38<E38,IF(OR(J38="Oui",'00_Parametres'!$B$28="Oui"),H38,E38),H38)) | M38: =IF(OR(A38="",I38=""),"",IF(I38>F38,IF(OR(K38="Oui",'00_Parametres'!$B$29="Oui"),I38,F38),I38)) | N38: =IF(OR(A38="",H38="",E38=""),0,MAX(0,ROUND((H38-E38)*1440,0))) -> 0 | O38: =IF(OR(A38="",I38="",F38=""),0,MAX(0,ROUND((F38-I38)*1440,0))) -> 0 | P38: =IF(OR(L38="",M38=""),0,MAX(0,ROUND((M38-L38)*24-G38,2))) -> 0 | Q38: =IF(P38=0,0,MIN(P38,'00_Parametres'!$B$23)) -> 0 | R38: =IF(P38=0,0,MAX(0,P38-'00_Parametres'!$B$23)) -> 0
A39: 46260 | B39: EMP005 | C39: =IF(B39="","",IFERROR(VLOOKUP(B39,Employes[[ID]:[Nom Complet]],4,FALSE()),"")) -> Abdou | D39: =IF(A39="","",TEXT(A39,"dddd")) -> 8/262026 | E39: =IF(A39="","",IFERROR(INDEX('00_Parametres'!$C$7:$C$13,WEEKDAY(A39,2)),"")) | F39: =IF(A39="","",IFERROR(INDEX('00_Parametres'!$D$7:$D$13,WEEKDAY(A39,2)),"")) | G39: =IF(A39="","",IFERROR(INDEX('00_Parametres'!$E$7:$E$13,WEEKDAY(A39,2)),0)) -> 0 | H39: 0.33333333 | J39: Non | K39: Non | L39: =IF(OR(A39="",H39=""),"",IF(H39<E39,IF(OR(J39="Oui",'00_Parametres'!$B$28="Oui"),H39,E39),H39)) | M39: =IF(OR(A39="",I39=""),"",IF(I39>F39,IF(OR(K39="Oui",'00_Parametres'!$B$29="Oui"),I39,F39),I39)) | N39: =IF(OR(A39="",H39="",E39=""),0,MAX(0,ROUND((H39-E39)*1440,0))) -> 0 | O39: =IF(OR(A39="",I39="",F39=""),0,MAX(0,ROUND((F39-I39)*1440,0))) -> 0 | P39: =IF(OR(L39="",M39=""),0,MAX(0,ROUND((M39-L39)*24-G39,2))) -> 0 | Q39: =IF(P39=0,0,MIN(P39,'00_Parametres'!$B$23)) -> 0 | R39: =IF(P39=0,0,MAX(0,P39-'00_Parametres'!$B$23)) -> 0
A40: 46260 | B40: EMP006 | C40: =IF(B40="","",IFERROR(VLOOKUP(B40,Employes[[ID]:[Nom Complet]],4,FALSE()),"")) -> Nyontyen Si Jean Vinny | D40: =IF(A40="","",TEXT(A40,"dddd")) -> 8/262026 | E40: =IF(A40="","",IFERROR(INDEX('00_Parametres'!$C$7:$C$13,WEEKDAY(A40,2)),"")) | F40: =IF(A40="","",IFERROR(INDEX('00_Parametres'!$D$7:$D$13,WEEKDAY(A40,2)),"")) | G40: =IF(A40="","",IFERROR(INDEX('00_Parametres'!$E$7:$E$13,WEEKDAY(A40,2)),0)) -> 0 | H40: 0.35555556 | J40: Non | K40: Non | L40: =IF(OR(A40="",H40=""),"",IF(H40<E40,IF(OR(J40="Oui",'00_Parametres'!$B$28="Oui"),H40,E40),H40)) | M40: =IF(OR(A40="",I40=""),"",IF(I40>F40,IF(OR(K40="Oui",'00_Parametres'!$B$29="Oui"),I40,F40),I40)) | N40: =IF(OR(A40="",H40="",E40=""),0,MAX(0,ROUND((H40-E40)*1440,0))) -> 0 | O40: =IF(OR(A40="",I40="",F40=""),0,MAX(0,ROUND((F40-I40)*1440,0))) -> 0 | P40: =IF(OR(L40="",M40=""),0,MAX(0,ROUND((M40-L40)*24-G40,2))) -> 0 | Q40: =IF(P40=0,0,MIN(P40,'00_Parametres'!$B$23)) -> 0 | R40: =IF(P40=0,0,MAX(0,P40-'00_Parametres'!$B$23)) -> 0
A41: 46260 | B41: EMP007 | C41: =IF(B41="","",IFERROR(VLOOKUP(B41,Employes[[ID]:[Nom Complet]],4,FALSE()),"")) -> Holé Homsala | D41: =IF(A41="","",TEXT(A41,"dddd")) -> 8/262026 | E41: =IF(A41="","",IFERROR(INDEX('00_Parametres'!$C$7:$C$13,WEEKDAY(A41,2)),"")) | F41: =IF(A41="","",IFERROR(INDEX('00_Parametres'!$D$7:$D$13,WEEKDAY(A41,2)),"")) | G41: =IF(A41="","",IFERROR(INDEX('00_Parametres'!$E$7:$E$13,WEEKDAY(A41,2)),0)) -> 0 | H41: 0.36319444 | J41: Non | K41: Non | L41: =IF(OR(A41="",H41=""),"",IF(H41<E41,IF(OR(J41="Oui",'00_Parametres'!$B$28="Oui"),H41,E41),H41)) | M41: =IF(OR(A41="",I41=""),"",IF(I41>F41,IF(OR(K41="Oui",'00_Parametres'!$B$29="Oui"),I41,F41),I41)) | N41: =IF(OR(A41="",H41="",E41=""),0,MAX(0,ROUND((H41-E41)*1440,0))) -> 0 | O41: =IF(OR(A41="",I41="",F41=""),0,MAX(0,ROUND((F41-I41)*1440,0))) -> 0 | P41: =IF(OR(L41="",M41=""),0,MAX(0,ROUND((M41-L41)*24-G41,2))) -> 0 | Q41: =IF(P41=0,0,MIN(P41,'00_Parametres'!$B$23)) -> 0 | R41: =IF(P41=0,0,MAX(0,P41-'00_Parametres'!$B$23)) -> 0
A42: 46260 | B42: EMP008 | C42: =IF(B42="","",IFERROR(VLOOKUP(B42,Employes[[ID]:[Nom Complet]],4,FALSE()),"")) -> Ebene Ngono | D42: =IF(A42="","",TEXT(A42,"dddd")) -> 8/262026 | E42: =IF(A42="","",IFERROR(INDEX('00_Parametres'!$C$7:$C$13,WEEKDAY(A42,2)),"")) | F42: =IF(A42="","",IFERROR(INDEX('00_Parametres'!$D$7:$D$13,WEEKDAY(A42,2)),"")) | G42: =IF(A42="","",IFERROR(INDEX('00_Parametres'!$E$7:$E$13,WEEKDAY(A42,2)),0)) -> 0 | H42: 0.35416667 | J42: Non | K42: Non | L42: =IF(OR(A42="",H42=""),"",IF(H42<E42,IF(OR(J42="Oui",'00_Parametres'!$B$28="Oui"),H42,E42),H42)) | M42: =IF(OR(A42="",I42=""),"",IF(I42>F42,IF(OR(K42="Oui",'00_Parametres'!$B$29="Oui"),I42,F42),I42)) | N42: =IF(OR(A42="",H42="",E42=""),0,MAX(0,ROUND((H42-E42)*1440,0))) -> 0 | O42: =IF(OR(A42="",I42="",F42=""),0,MAX(0,ROUND((F42-I42)*1440,0))) -> 0 | P42: =IF(OR(L42="",M42=""),0,MAX(0,ROUND((M42-L42)*24-G42,2))) -> 0 | Q42: =IF(P42=0,0,MIN(P42,'00_Parametres'!$B$23)) -> 0 | R42: =IF(P42=0,0,MAX(0,P42-'00_Parametres'!$B$23)) -> 0
...

Sheet 03_Paie
A1: CALCUL DE PAIE — BASÉ SUR LES HEURES RÉELLES + PRIMES DE TÂCHE
A2: Sélectionnez la période. Les heures, primes et salaires se calculent automatiquement à partir du Pointage et des paramètres employés.
A4: PÉRIODE DE CALCUL
A5: Date début | B5: 46235 | C5: Date fin | D5: 46265 | E5: ← Modifiez ces dates pour recalculer sur n'importe quelle période
A7: SYNTHÈSE PÉRIODE
A8: Total Heures Normales | B8: =G27 -> 164.12 | C8: Total Heures Supp | D8: =H27 -> 1 | E8: Total Primes Tâches | F8: =I27 -> 7500 | G8: Masse Salariale Estimée | H8: =L27 -> 86433
A11: ID | B11: Nom Complet | C11: Poste | D11: Type Contrat | E11: Salaire Base Mensuel | F11: Taux Horaire | G11: Heures Normales | H11: Heures Supp. | I11: Total Primes Tâches | J11: Montant Heures Normales | K11: Montant HS | L11: Salaire Brut Estimé | M11: Jours Présents | N11: Observations
A12: =IF('01_Employes'!A6="","",'01_Employes'!A6) -> EMP001 | B12: =IF(A12="","",'01_Employes'!D6) -> Tsafack Ndongmo Symphonien | C12: =IF(A12="","",'01_Employes'!E6) -> Administrateur | D12: =IF(A12="","",'01_Employes'!K6) -> CDI | E12: =IF(A12="","",'01_Employes'!L6) -> 150000 | F12: =IF(A12="","",'01_Employes'!M6) -> 666 | G12: =IF(A12="","",SUMIFS(Pointage[Heures Normales],Pointage[ID Employé],A12,Pointage[Date],">="&$B$5,Pointage[Date],"<="&$D$5)) -> 16.83 | H12: =IF(A12="","",SUMIFS(Pointage[Heures Supp.],Pointage[ID Employé],A12,Pointage[Date],">="&$B$5,Pointage[Date],"<="&$D$5)) -> 0 | I12: =IF(A12="","",SUMIFS(Pointage[Prime Tâche (FCFA)],Pointage[ID Employé],A12,Pointage[Date],">="&$B$5,Pointage[Date],"<="&$D$5)) -> 0 | J12: =IF(OR(A12="",F12=""),0,ROUND(G12*F12,0)) -> 11209 | K12: =IF(OR(A12="",H12=""),0,ROUND(H12*'01_Employes'!N6,0)) -> 0 | L12: =IF(A12="","",J12+K12+I12) -> 11209 | M12: =IF(A12="","",COUNTIFS(Pointage[ID Employé],A12,Pointage[Date],">="&$B$5,Pointage[Date],"<="&$D$5,Pointage[Heures travaillées],">0")) -> 2
A13: =IF('01_Employes'!A7="","",'01_Employes'!A7) -> EMP002 | B13: =IF(A13="","",'01_Employes'!D7) -> Pandja Tchatchoua Syriane | C13: =IF(A13="","",'01_Employes'!E7) -> Secrétaire | D13: =IF(A13="","",'01_Employes'!K7) -> CDI | E13: =IF(A13="","",'01_Employes'!L7) -> 100000 | F13: =IF(A13="","",'01_Employes'!M7) -> 444 | G13: =IF(A13="","",SUMIFS(Pointage[Heures Normales],Pointage[ID Employé],A13,Pointage[Date],">="&$B$5,Pointage[Date],"<="&$D$5)) -> 15 | H13: =IF(A13="","",SUMIFS(Pointage[Heures Supp.],Pointage[ID Employé],A13,Pointage[Date],">="&$B$5,Pointage[Date],"<="&$D$5)) -> 1 | I13: =IF(A13="","",SUMIFS(Pointage[Prime Tâche (FCFA)],Pointage[ID Employé],A13,Pointage[Date],">="&$B$5,Pointage[Date],"<="&$D$5)) -> 5000 | J13: =IF(OR(A13="",F13=""),0,ROUND(G13*F13,0)) -> 6660 | K13: =IF(OR(A13="",H13=""),0,ROUND(H13*'01_Employes'!N7,0)) -> 666 | L13: =IF(A13="","",J13+K13+I13) -> 12326 | M13: =IF(A13="","",COUNTIFS(Pointage[ID Employé],A13,Pointage[Date],">="&$B$5,Pointage[Date],"<="&$D$5,Pointage[Heures travaillées],">0")) -> 2
A14: =IF('01_Employes'!A8="","",'01_Employes'!A8) -> EMP003 | B14: =IF(A14="","",'01_Employes'!D8) -> Takoueta Yvan | C14: =IF(A14="","",'01_Employes'!E8) -> Chef des ateliers | D14: =IF(A14="","",'01_Employes'!K8) -> CDI | E14: =IF(A14="","",'01_Employes'!L8) -> 150000 | F14: =IF(A14="","",'01_Employes'!M8) -> 666 | G14: =IF(A14="","",SUMIFS(Pointage[Heures Normales],Pointage[ID Employé],A14,Pointage[Date],">="&$B$5,Pointage[Date],"<="&$D$5)) -> 16.5 | H14: =IF(A14="","",SUMIFS(Pointage[Heures Supp.],Pointage[ID Employé],A14,Pointage[Date],">="&$B$5,Pointage[Date],"<="&$D$5)) -> 0 | I14: =IF(A14="","",SUMIFS(Pointage[Prime Tâche (FCFA)],Pointage[ID Employé],A14,Pointage[Date],">="&$B$5,Pointage[Date],"<="&$D$5)) -> 0 | J14: =IF(OR(A14="",F14=""),0,ROUND(G14*F14,0)) -> 10989 | K14: =IF(OR(A14="",H14=""),0,ROUND(H14*'01_Employes'!N8,0)) -> 0 | L14: =IF(A14="","",J14+K14+I14) -> 10989 | M14: =IF(A14="","",COUNTIFS(Pointage[ID Employé],A14,Pointage[Date],">="&$B$5,Pointage[Date],"<="&$D$5,Pointage[Heures travaillées],">0")) -> 2
A15: =IF('01_Employes'!A9="","",'01_Employes'!A9) -> EMP004 | B15: =IF(A15="","",'01_Employes'!D9) -> Chekep Faustin | C15: =IF(A15="","",'01_Employes'!E9) -> Mécanicien | D15: =IF(A15="","",'01_Employes'!K9) -> CDI | E15: =IF(A15="","",'01_Employes'!L9) -> 120000 | F15: =IF(A15="","",'01_Employes'!M9) -> 533 | G15: =IF(A15="","",SUMIFS(Pointage[Heures Normales],Pointage[ID Employé],A15,Pointage[Date],">="&$B$5,Pointage[Date],"<="&$D$5)) -> 18.2 | H15: =IF(A15="","",SUMIFS(Pointage[Heures Supp.],Pointage[ID Employé],A15,Pointage[Date],">="&$B$5,Pointage[Date],"<="&$D$5)) -> 0 | I15: =IF(A15="","",SUMIFS(Pointage[Prime Tâche (FCFA)],Pointage[ID Employé],A15,Pointage[Date],">="&$B$5,Pointage[Date],"<="&$D$5)) -> 0 | J15: =IF(OR(A15="",F15=""),0,ROUND(G15*F15,0)) -> 9701 | K15: =IF(OR(A15="",H15=""),0,ROUND(H15*'01_Employes'!N9,0)) -> 0 | L15: =IF(A15="","",J15+K15+I15) -> 9701 | M15: =IF(A15="","",COUNTIFS(Pointage[ID Employé],A15,Pointage[Date],">="&$B$5,Pointage[Date],"<="&$D$5,Pointage[Heures travaillées],">0")) -> 2
A16: =IF('01_Employes'!A10="","",'01_Employes'!A10) -> EMP005 | B16: =IF(A16="","",'01_Employes'!D10) -> Abdou | C16: =IF(A16="","",'01_Employes'!E10) -> Tôlier | D16: =IF(A16="","",'01_Employes'!K10) -> Apprentissage | E16: =IF(A16="","",'01_Employes'!L10) -> 80000 | F16: =IF(A16="","",'01_Employes'!M10) -> 355 | G16: =IF(A16="","",SUMIFS(Pointage[Heures Normales],Pointage[ID Employé],A16,Pointage[Date],">="&$B$5,Pointage[Date],"<="&$D$5)) -> 12.5 | H16: =IF(A16="","",SUMIFS(Pointage[Heures Supp.],Pointage[ID Employé],A16,Pointage[Date],">="&$B$5,Pointage[Date],"<="&$D$5)) -> 0 | I16: =IF(A16="","",SUMIFS(Pointage[Prime Tâche (FCFA)],Pointage[ID Employé],A16,Pointage[Date],">="&$B$5,Pointage[Date],"<="&$D$5)) -> 2500 | J16: =IF(OR(A16="",F16=""),0,ROUND(G16*F16,0)) -> 4438 | K16: =IF(OR(A16="",H16=""),0,ROUND(H16*'01_Employes'!N10,0)) -> 0 | L16: =IF(A16="","",J16+K16+I16) -> 6938 | M16: =IF(A16="","",COUNTIFS(Pointage[ID Employé],A16,Pointage[Date],">="&$B$5,Pointage[Date],"<="&$D$5,Pointage[Heures travaillées],">0")) -> 2
A17: =IF('01_Employes'!A11="","",'01_Employes'!A11) -> EMP006 | B17: =IF(A17="","",'01_Employes'!D11) -> Nyontyen Si Jean Vinny | C17: =IF(A17="","",'01_Employes'!E11) -> Mécanicien | D17: =IF(A17="","",'01_Employes'!K11) -> Apprentissage | E17: =IF(A17="","",'01_Employes'!L11) -> 80000 | F17: =IF(A17="","",'01_Employes'!M11) -> 355 | G17: =IF(A17="","",SUMIFS(Pointage[Heures Normales],Pointage[ID Employé],A17,Pointage[Date],">="&$B$5,Pointage[Date],"<="&$D$5)) -> 18.15 | H17: =IF(A17="","",SUMIFS(Pointage[Heures Supp.],Pointage[ID Employé],A17,Pointage[Date],">="&$B$5,Pointage[Date],"<="&$D$5)) -> 0 | I17: =IF(A17="","",SUMIFS(Pointage[Prime Tâche (FCFA)],Pointage[ID Employé],A17,Pointage[Date],">="&$B$5,Pointage[Date],"<="&$D$5)) -> 0 | J17: =IF(OR(A17="",F17=""),0,ROUND(G17*F17,0)) -> 6443 | K17: =IF(OR(A17="",H17=""),0,ROUND(H17*'01_Employes'!N11,0)) -> 0 | L17: =IF(A17="","",J17+K17+I17) -> 6443 | M17: =IF(A17="","",COUNTIFS(Pointage[ID Employé],A17,Pointage[Date],">="&$B$5,Pointage[Date],"<="&$D$5,Pointage[Heures travaillées],">0")) -> 2
A18: =IF('01_Employes'!A12="","",'01_Employes'!A12) -> EMP007 | B18: =IF(A18="","",'01_Employes'!D12) -> Holé Homsala | C18: =IF(A18="","",'01_Employes'!E12) -> Magasinier | D18: =IF(A18="","",'01_Employes'!K12) -> Apprentissage | E18: =IF(A18="","",'01_Employes'!L12) -> 80000 | F18: =IF(A18="","",'01_Employes'!M12) -> 355 | G18: =IF(A18="","",SUMIFS(Pointage[Heures Normales],Pointage[ID Employé],A18,Pointage[Date],">="&$B$5,Pointage[Date],"<="&$D$5)) -> 9.43 | H18: =IF(A18="","",SUMIFS(Pointage[Heures Supp.],Pointage[ID Employé],A18,Pointage[Date],">="&$B$5,Pointage[Date],"<="&$D$5)) -> 0 | I18: =IF(A18="","",SUMIFS(Pointage[Prime Tâche (FCFA)],Pointage[ID Employé],A18,Pointage[Date],">="&$B$5,Pointage[Date],"<="&$D$5)) -> 0 | J18: =IF(OR(A18="",F18=""),0,ROUND(G18*F18,0)) -> 3348 | K18: =IF(OR(A18="",H18=""),0,ROUND(H18*'01_Employes'!N12,0)) -> 0 | L18: =IF(A18="","",J18+K18+I18) -> 3348 | M18: =IF(A18="","",COUNTIFS(Pointage[ID Employé],A18,Pointage[Date],">="&$B$5,Pointage[Date],"<="&$D$5,Pointage[Heures travaillées],">0")) -> 2
